Workbook

Sheet IND
B3: 1 | C3: Этап_210. Исследование Исследование и описание внутренних источников, выгрузка тестовых данных, мониторинг изменений источников
C5: Параметр | E5: Кол-во Указать | F5: Коэф. К Базе Фиксир. | G5: Оценка, чд
C6: 1. Кол-во Источников к Исследованию (с репликой в ДАПП) | E6: 1 | F6: 1 | G6: =G$21*E6*F6 -> 14
C7: 2. Кол-во Источников к Исследованию (без реплики в ДАПП) | F7: 1.5 | G7: =G$21*E7*F7 -> 0
C8: 3. Требования по Источникам не понятны (кол-во Источников) *Доп трудозатраты на сбор требований/аналитику по 1 источнику/тематике Из п.1+п.2 | E8: 1 | F8: 0.3 | G8: =G$21*E8*F8 -> 4.2
C9: 4.Кол-во доп неопределенных на данный момент Источников/Тематик (риск привнесения новых требований) | E9: 0 | F9: 1.5 | G9: =G$21*E9*F9 -> 0
C10: Оценка,чд | G10: =SUM(G6:G9) -> 18.2
C11: Дополнительно
C12: Перечень стандартных задач (База) Исследование 1 Источника, с репликой в ДАПП и четко определенными требованиями
C13: Задача | G13: Емкость, ч/д
C14: Уточнение требований, сбор первичной информации | G14: 1
C15: Исследование Источника/Поиск Данных | G15: 2
C16: Анализ Данных/Связок/Проверка качества | G16: 3
C17: Проработка вопросов с контрагентами | G17: 3
C18: Организация выгрузок | G18: 2
C19: Оформление Аналитической Записки | G19: 1
C20: Расследование проблем с качеством/контроль устранения | G20: 2
E21: База,чд | G21: =SUM(G14:G20) -> 14
B25: 2 | C25: Этап_211. Разработка БТ (Витрина/Интеграция) Разработка БТ (ТР) по реализации процесса загрузки данных или по витринам на внешних/внутренних данных
C27: Параметр | E27: Кол-во Указать | F27: Коэф. К Базе Фиксир. | G27: Оценка, чд
C28: A. Требуется БТ на разработку витрины !Первый этап - заложить исследование Источников для БТ на витрину (См. этап 210)
C29: Кол-во источников в витрине | E29: 1 | F29: формула | G29: =ROUND(IF(E29<6, G51, E29/5*G51), 0) -> 22 | I29: Если иточников <6, берем чд из базы, если больше получает коэф и умножаем на базу чд + округление
C30: Кол-во неопределенных на данный момент Источников/Метрик с неопредел.логикой расчета (риск привнесения новых требований) | E30: 0 | F30: 10 | G30: =E30*F30 -> 0
C31: Оценка БТ Витрина,чд | G31: =SUM(G29:G30) -> 22
C32: След.шаг по выводу витрины/оценке работ - Запрос оценки Смежного Стрима (Витрины и Сервисы Озера Данных) - Проработка возможности вывода витрины силами Стрима Облако Данных - только с участием внешних данных в витрине + только цели ДАДМ
C34: B. Требуется БТ на интеграцию Источника в ПД
C35: Кол-во источников к интеграции в ПД(Высокая готовность (не требуются доработки)+простая архитектура) | E35: 1 | F35: 0.5 | G35: =G$51*E35*F35 -> 11
C36: Кол-во источников к интеграции в ПД(Доработки ИС (ЛМД,и т.д)+простая архитектура) | E36: 0 | F36: 0.8 | G36: =G$51*E36*F36 -> 0
C37: Кол-во источников сложная интеграция (проработка архитектуры,доработка источника) | E37: 0 | F37: 1.2 | G37: =G$51*E37*F37 -> 0
C38: Оценка БТ Интеграция,чд | G38: =SUM(G35:G37) -> 11
C39: След.шаг по выводу интеграции в ПРОМ/оценке работ - Запрос оценки Смежного Стрима (Озера Данных+Поддержка Озера ДАнных+доп Стримы, если участвуют)
C40: Дополнительно
C41: Перечень стандартных задач (База) База для БТ Стандартная Витрина(не более 5 понятных источников)/БТ Источник Готов к Интеграции
C42: Задача | G42: Емкость, ч/д
C43: Сбор начальных требований | G43: 2
C44: Анализ Источников | G44: 4
C45: Постановка RDS/План/Сроки | G45: 3
C46: Описание Бизнес Требования (Шаблон) | G46: 1
C47: Проработка связок/Архитектуры | G47: 4
C48: Формирование прототипа/Проработка Технич вопросов | G48: 5
...

Sheet OUT 214 И. внеш
B1: Исследование и описание внешних источников, выгрузка тестовых данных, мониторинг изменений источников
B2: Параметр работ | C2: Значение параметра | E2: Влияние | F2: вар 1 | G2: вар 2 | H2: вар 3 | I2: вар 4 | J2: вар 5 | K2: вар 6 | L2: вар 7
B3: Инициировано предыдущим этапом (например, инициировано загрузкой, в которой уже прошла часть аналитики) | C3: Нет | E3: =IF(C3="Нет", G3, IF(C3="Да", H3, "")) -> 1 | G3: 1 | H3: 0.75
B4: Сложность предметной области. Оценивается лидером команды/стрима исполнителя на основании опыта и профиля команды. | C4: Средняя | E4: =IF(C4="Неизвестно", F4, IF(C4="Низкая", G4, IF(C4="Средняя", H4, IF(C4="Высокая", I4, "")))) -> 1 | F4: 1.25 | G4: 0.75 | H4: 1 | I4: 1.5
B5: Объем запроса по сущностям. Ориентировочное соответствие оценки к сущностям: Т: 1-4 М: 5-9 С: 9-15 К: 15-20 Б: 20-25 М: 25+. Соответствие не точное и может отличаться. Оценивается лидером команды/стрима исполнителя на опыте работы с подобными сущностями и количества описывающих сущность атрибутов. | C5: Среднее | E5: =IF(C5="Неизвестно", F5, IF(C5="Точечное", G5, IF(C5="Малое", H5, IF(C5="Среднее", I5, IF(C5="Крупное", J5, IF(C5="Большое", K5, IF(C5="Масштабное", L5, ""))))))) -> 1 | F5: 1.25 | G5: 0.5 | H5: 0.75 | I5: 1 | J5: 1.25 | K5: 1.5 | L5: 1.75
B6: Детализация и ясность запроса в RDS или ином артефакте, предоставляемые заказчиком | C6: Неизвестно | E6: =IF(C6="Неизвестно", F6, IF(C6="Низкая", G6, IF(C6="Средняя", H6, IF(C6="Высокая", I6, "")))) -> 1 | F6: 1 | G6: 1.5 | H6: 1.25 | I6: 0.75
B7: Определены ли исследуемые источник(и) или исследование предполагает их поиск | C7: Неизвестно | E7: =IF(C7="Неизвестно", F7, IF(C7="Да", G7, IF(C7="Нет", H7, ""))) -> 1 | F7: 1 | G7: 0.75 | H7: 1.25
B8: Конкретизированы ли искомые данные или состав/объём данных понадобится в каждом источнике определять в согласовании с заказчиком | C8: Неизвестно | E8: =IF(C8="Неизвестно", F8, IF(C8="Да", G8, IF(C8="Нет", H8, ""))) -> 1 | F8: 1 | G8: 0.75 | H8: 1.25
B9: Необходимо ли заключение NDA | C9: Неизвестно | E9: =IF(C9="Неизвестно", F9, IF(C9="Да", G9, IF(C9="Нет", H9, ""))) -> 1 | F9: 1 | G9: 1.25 | H9: 0
B10: Согласен ли Источник на стандартную форму NDA | C10: Неизвестно | E10: =IF(C10="Неизвестно", F10, IF(C10="Да", G10, IF(C10="Нет", H10, ""))) -> 1 | F10: 1 | G10: 0.75 | H10: 1.25
B11: Предмет исследования включает в себя конфиденциальные данные | C11: Неизвестно | E11: =IF(C11="Неизвестно", F11, IF(C11="Да", G11, IF(C11="Нет", H11, ""))) -> 1 | F11: 1 | G11: 1.25 | H11: 0
B12: 214 Состав работ команды Внешние Данные | C12: Объём, чд | F12: база | G12: зависимость
B13: Интервьюирование заказчика, подтверждение финансирования и обработка RDS | C13: =CEILING(F13*(1+G13*E$4*E$5*E$6*E$7*E$8)*E$3, 0.1) -> 0.7 | F13: 0.5 | G13: 0.31
B14: Планирование и работа с бэклогом | C14: =CEILING(F14*(1+G14*(E$3*E$4*E$5*E$6*E$7*E$8+E$9*E$10+E$11)), 0.1) -> 1 | F14: 0.5 | G14: 0.33
B15: Сбор и анализ требований | C15: =CEILING(F15*(1+G15*(E$4*E$5*E$6*E$7*E$8+E$11))*E$3, 0.1) -> 0.9 | F15: 0.5 | G15: 0.4
B16: Поиск и анализ источника(ов) и данных | C16: =CEILING(F16*(1+G16*(E$3*E$4*E$6*E$8+E$9*E$10+E$11))*(E5*E7), 0.1) -> 2.7 | F16: 1 | G16: 0.55
B17: Подготовка АЗ для заключения NDA, согласование содержания NDA | C17: =CEILING(F17*(1+G17*(E$3*E$4*E$5+E$11))*(E$9*E$10), 0.1) -> 0.6 | F17: 0.5 | G17: 0.07
B18: Получение визы от ИБ и ЮБ по возможности обмена конфиденциальными данными | C18: =CEILING(F18*(1+G18*(E$3*E$4*E$5))*E$11, 0.1) -> 0.7 | F18: 0.5 | G18: 0.25
B19: Подготовка Отчета о проведенном Исследовании и согласование результата | C19: =CEILING(F19*(1+G19*(E$3+E$11))*(E$4*E$5), 0.1) -> 0.8 | F19: 0.5 | G19: 0.22
B20: Доработка внутренней документации и информационных ресурсов группы | C20: =CEILING(F20*(1+G20*(E$5+E$9))*E$3, 0.1) -> 1 | F20: 0.5 | G20: 0.45
B21: ИТОГО: | C21: =ROUND(SUM(C13:C20), 0) -> 8
C22: =C21*Параметры!$B$2 -> 243200

Sheet OUT 21520 Пилот
B1: Проведение пилота по внешним данным
B2: Параметр работ | C2: Значение параметра | E2: Влияние | F2: вар 1 | G2: вар 2 | H2: вар 3 | I2: вар 4 | J2: вар 5 | K2: вар 6 | L2: вар 7
B3: Инициировано предыдущим этапом (например, инициировано загрузкой, в которой уже прошла часть аналитики) | C3: Нет | E3: =IF(C3="Нет", G3, IF(C3="Да", H3, "")) -> 1 | G3: 1 | H3: 0.75
B4: Новый пилот или повторный | C4: Новый | E4: =IF(C4="Неизвестно", F4, IF(C4="Новый", G4, IF(C4="Повторный", H4, ""))) -> 1.1 | F4: 1 | G4: 1.1 | H4: 0.75
B5: Сложность предметной области. Оценивается лидером команды/стрима исполнителя на основании опыта и профиля команды. | C5: Средняя | E5: =IF(C5="Неизвестно", F5, IF(C5="Низкая", G5, IF(C5="Средняя", H5, IF(C5="Высокая", I5, "")))) -> 1 | F5: 1.25 | G5: 0.75 | H5: 1 | I5: 1.5
B6: Объем запроса по сущностям. Ориентировочное соотвествие оценки к сущностям: Т: 1-4 М: 5-9 С: 9-15 К: 15-20 Б: 20-25 М: 25+. Соотвествие не точное и может отличаться. Оценивается лидером команды/стрима исполнителя на опыта работы с подобными сущностями и количества описывающих сущность атрибутов. | C6: Среднее | E6: =IF(C6="Неизвестно", F6, IF(C6="Точечное", G6, IF(C6="Малое", H6, IF(C6="Среднее", I6, IF(C6="Крупное", J6, IF(C6="Большое", K6, IF(C6="Масштабное", L6, ""))))))) -> 1 | F6: 1.25 | G6: 0.5 | H6: 0.75 | I6: 1 | J6: 1.25 | K6: 1.5 | L6: 1.75
B7: Детализация и ясность запроса в RDS или ином артефакте, предоставляемые заказчиком | C7: Неизвестно | E7: =IF(C7="Неизвестно", F7, IF(C7="Низкая", G7, IF(C7="Средняя", H7, IF(C7="Высокая", I7, "")))) -> 1 | F7: 1 | G7: 1.5 | H7: 1.25 | I7: 0.75
B8: Необходимо ли заключение NDA | C8: Неизвестно | E8: =IF(C8="Неизвестно", F8, IF(C8="Да", G8, IF(C8="Нет", H8, ""))) -> 1 | F8: 1 | G8: 1.25 | H8: 0
B9: Согласен ли Источник на стандартную форму NDA | C9: Неизвестно | E9: =IF(C9="Неизвестно", F9, IF(C9="Да", G9, IF(C9="Нет", H9, ""))) -> 1 | F9: 1 | G9: 0.75 | H9: 1.25
B10: Есть ли юридические основания для проведения пилота / разовой загрузки | C10: Неизвестно | E10: =IF(C10="Неизвестно", F10, IF(C10="Да", G10, IF(C10="Нет", H10, ""))) -> 1 | F10: 1 | G10: 0 | H10: 1.25
B11: Пилот / разовая загрузка предусматривает обмен конфиденциальными данными | C11: Неизвестно | E11: =IF(C11="Неизвестно", F11, IF(C11="Да", G11, IF(C11="Нет", H11, ""))) -> 1 | F11: 1 | G11: 1.25 | H11: 0
B12: Пилот / разовая загрузка предусматривает хэширование/шифрование | C12: Неизвестно | E12: =IF(C12="Неизвестно", F12, IF(C12="Да", G12, IF(C12="Нет", H12, ""))) -> 1 | F12: 1 | G12: 1.25 | H12: 0.9
B13: Пилот / разовая загрузка предусматривает двусторонний обмен данными | C13: Неизвестно | E13: =IF(C13="Неизвестно", F13, IF(C13="Да", G13, IF(C13="Нет", H13, ""))) -> 1 | F13: 1 | G13: 1.25 | H13: 0.9
B14: Предусматривает ли пилот разовую загрузку командой Облако в ИС харнения Банка? | C14: Неизвестно | E14: =IF(C14="Неизвестно", F14, IF(C14="Да", G14, IF(C14="Нет", H14, ""))) -> 1 | F14: 1 | G14: 1.25 | H14: 0
B15: ИТОГО по стриму "Источники данных": | C15: =CEILING(SUM(C28, C37), 1) -> 12
C16: =C15*Параметры!$B$2 -> 364800
B17: 215 Состав работ команды Внешние Данные | C17: Объём, чд | F17: база | G17: зависимость
B18: Интервьюирование заказчика, подтверждение финансирования и обработка RDS | C18: =CEILING(F18*(1+G18*(E$4*E$5*E$6*E$7*E$13*E$12))*E$3, 0.1) -> 0.7 | F18: 0.5 | G18: 0.3
B19: Планирование и работа с бэклогом | C19: =CEILING(F19*(1+G19*(E$3*E$4*E$5*E$6*E$7*E$12*E$13+E$8*E$9+E$10+E$11)), 0.1) -> 0.9 | F19: 0.5 | G19: 0.19
B20: Сбор и анализ требований | C20: =CEILING(F20*(1+G20*(E$4*E$5*E$6*E$7*E$12*E$13+E$11))*E$3, 0.1) -> 0.9 | F20: 0.5 | G20: 0.36
B21: Подготовка АЗ для заключения NDA, согласование содержания NDA | C21: =CEILING(F21*(1+G21*(E$3*E$4*E$5*E$6+E$13+E$11))*(E$8*E$9), 0.1) -> 0.6 | F21: 0.5 | G21: 0.05
B22: Согласование пилота / разовой загрузки с ИБ и ЮБ | C22: =CEILING(F22*(1+G22*(E$3*E$4*E$5*E$6+E$13))*E$11, 0.1) -> 0.7 | F22: 0.5 | G22: 0.14
B23: Оперативное обеспечение юридического основания или инициация этапа | C23: =CEILING(F23*(1+G23*(E$3*E$4*E$5*E$6+E$11+E$13))*E10, 0.1) -> 0.7 | F23: 0.5 | G23: 0.11
B24: Организация и контроль проведения пилота / разовой загрузки | C24: =CEILING(F24*(1+G24*(E$3*E$5*E$7+E$11))*(E$4*E$6*E$13*E$12), 0.1) -> 1.8 | F24: 1 | G24: 0.29
B25: Прием и анализ результатов пилота / разовой загрузки | C25: =CEILING(F25*(1+G25*(E$12*E$13+E$11))*(E$5*E$6), 0.1) -> 0.7 | F25: 0.5 | G25: 0.2
B26: Подготовка Отчета о проведении пилота / разовой загрузки и согласование результата | C26: =CEILING(F26*(1+G26*(E$3*E$4*E$12*E$13+E$11))*(E$5*E$6), 0.1) -> 0.7 | F26: 0.5 | G26: 0.18
B27: Доработка внутренней документации и инфрмационных ресурсов группы | C27: =CEILING(F27*(1+G27*(E$6+E$8+E$10))*(E$3*E$4), 0.1) -> 0.9 | F27: 0.5 | G27: 0.2
B28: ИТОГО: | C28: =CEILING(SUM(C18:C27), 1) -> 9
C29: =C28*Параметры!$B$2 -> 273600
B30: 220 Состав работ команды Облако данных ETL / DANN | C30: Объём, чд | F30: база | G30: зависимость | H30: макс
B31: Планирование и работа с бэклогом | C31: =CEILING(F31*(1+G31*(E$4*E$5*E$6*E$13*E$12))*(E$3*E$14), 0.1) -> 0.6 | F31: 0.5 | G31: 0.13 | H31: 1
B32: Согласование и корректировка входящих требований | C32: =CEILING(F32*(1+G32*(E$4*E$5*E$6*E$13*E$12))*(E$3*E$14), 0.1) -> 0.8 | F32: 0.5 | G32: 0.46 | H32: 2
B33: Согласование и проверка модели данных s2t | C33: =CEILING(F33*(1+G33*(E$4*E$5*E$6*E$13*E$12))*(E$3*E$14), 0.1) -> 0.6 | F33: 0.5 | G33: 0.13 | H33: 1
B34: Работы по разворачиванию и настройке новой инфраструктуры | C34: =CEILING(F34*(1+G34*(E$4*E$5*E$6*E$13*E$12))*(E$3*E$14), 0.1) -> 0.8 | F34: 0.5 | G34: 0.46 | H34: 2
B35: Загрузка данных в ИС хранения Банка | C35: =CEILING(F35*(1+G35*(E$4*E$5*E$6*E$13*E$12))*(E$3*E$14), 0.1) -> 0.8 | F35: 0.5 | G35: 0.46 | H35: 2
B36: Доработка внутренней документации и инфрмационных ресурсов группы | C36: =CEILING(F36*(1+G36*(E$4*E$5*E$6*E$13*E$12))*(E$3*E$14), 0.1) -> 0.6 | F36: 0.5 | G36: 0.13 | H36: 1
B37: ИТОГО: | C37: =CEILING(SUM(C34:C36), 1) -> 3
C38: =C37*Параметры!$B$2 -> 91200
B40: бэклог 1чд
B41: Оперативное обеспечение юридического основания или инициация этапа
...

Sheet OUT 216 ЮО
B1: Сопровождение юридического обеспечения (ЮО) отношений Банка с Источником внешних данных
B2: Параметр работ | C2: Значение параметра | E2: Влияние | F2: вар 1 | G2: вар 2 | H2: вар 3 | I2: вар 4 | J2: вар 5 | K2: вар 6 | L2: вар 7
B3: Инициировано предыдущим этапом (например, инициировано загрузкой, в которой уже прошла часть аналитики) | C3: Нет | E3: =IF(C3="Нет", G3, IF(C3="Да", H3, "")) -> 1 | G3: 1 | H3: 0.75
B4: Сложность предметной области. Оценивается лидером команды/стрима исполнителя на основании опыта и профиля команды. | C4: Средняя | E4: =IF(C4="Неизвестно", F4, IF(C4="Низкая", G4, IF(C4="Средняя", H4, IF(C4="Высокая", I4, "")))) -> 1 | F4: 1.25 | G4: 0.75 | H4: 1 | I4: 1.5
B5: Объем запроса по сущностям. Ориентировочное соотвествие оценки к сущностям: Т: 1-4 М: 5-9 С: 9-15 К: 15-20 Б: 20-25 М: 25+. Соотвествие не точное и может отличаться. Оценивается лидером команды/стрима исполнителя на опыта работы с подобными сущностями и количества описывающих сущность атрибутов. | C5: Среднее | E5: =IF(C5="Неизвестно", F5, IF(C5="Точечное", G5, IF(C5="Малое", H5, IF(C5="Среднее", I5, IF(C5="Крупное", J5, IF(C5="Большое", K5, IF(C5="Масштабное", L5, ""))))))) -> 1 | F5: 1.25 | G5: 0.5 | H5: 0.75 | I5: 1 | J5: 1.25 | K5: 1.5 | L5: 1.75
B6: Детализация и ясность запроса в RDS или ином артефакте, предоставляемые заказчиком | C6: Неизвестно | E6: =IF(C6="Неизвестно", F6, IF(C6="Низкая", G6, IF(C6="Средняя", H6, IF(C6="Высокая", I6, "")))) -> 1 | F6: 1 | G6: 1.5 | H6: 1.25 | I6: 0.75
B7: Необходимо ли заключение NDA | C7: Неизвестно | E7: =IF(C7="Неизвестно", F7, IF(C7="Да", G7, IF(C7="Нет", H7, ""))) -> 1 | F7: 1 | G7: 1.25 | H7: 0
B8: Согласен ли Источник на стандартную форму NDA | C8: Неизвестно | E8: =IF(C8="Неизвестно", F8, IF(C8="Да", G8, IF(C8="Нет", H8, ""))) -> 1 | F8: 1 | G8: 0.75 | H8: 1.25
B9: Договор предусматривает регламентную или разовую загрузу | C9: Неизвестно | E9: =IF(C9="Неизвестно", F9, IF(C9="Да", G9, IF(C9="Нет", H9, ""))) -> 1 | F9: 1 | G9: 1.25 | H9: 0.75
B10: Предусмотрено ли проведение соревновательной процедуры (конкурса) | C10: Неизвестно | E10: =IF(C10="Неизвестно", F10, IF(C10="Да", G10, IF(C10="Нет", H10, ""))) -> 1 | F10: 1 | G10: 1.25 | H10: 0
B11: Согласен ли Источник на стандартную форму договора Банка | C11: Неизвестно | E11: =IF(C11="Неизвестно", F11, IF(C11="Да", G11, IF(C11="Нет", H11, ""))) -> 1 | F11: 1 | G11: 0.75 | H11: 1.25
B12: Договор предусматривает обмен конфиденциальными данными | C12: Неизвестно | E12: =IF(C12="Неизвестно", F12, IF(C12="Да", G12, IF(C12="Нет", H12, ""))) -> 1 | F12: 1 | G12: 1.25 | H12: 0
B13: Договор предусматривает двусторонний обмен данными | C13: Неизвестно | E13: =IF(C13="Неизвестно", F13, IF(C13="Да", G13, IF(C13="Нет", H13, ""))) -> 1 | F13: 1 | G13: 1.25 | H13: 0.75
B14: 216 Состав работ команды Внешние Данные | C14: Объём, чд | F14: база | G14: зависимость
B15: Интервьюирование заказчика, подтверждение финансирования и обработка RDS | C15: =CEILING(F15*(1+G15*(E$4*E$5*E6*E13+E10))*E$3, 0.1) -> 0.7 | F15: 0.5 | G15: 0.15
B16: Планирование и работа с бэклогом | C16: =CEILING(F16*(1+G16*(E$3*E$4*E$6*E$9*E$11*E$13+E$7*E$8+E$10+E$12))*E$5, 0.1) -> 0.6 | F16: 0.5 | G16: 0.015
B17: Сбор и анализ требований | C17: =CEILING(F17*(1+G17*(E$4*E$5*E$6*E$9*E$13+E$10+E$12))*E$3, 0.1) -> 1 | F17: 0.5 | G17: 0.33
B18: Подготовка АЗ для заключения NDA, согласование содержания NDA | C18: =CEILING(F18*(1+G18*(E$3*E$4*E$5*E$9*E$13+E$12))*(E$7*E$8), 0.1) -> 0.6 | F18: 0.5 | G18: 0.05
B19: Согласование интеграции с ИБ и ЮБ | C19: =CEILING(F19*(1+G19*(E$3*E$4*E$5*E9*E13))*E12, 0.1) -> 0.6 | F19: 0.5 | G19: 0.11
B20: Подготовка ТЗ для проведения соревновательной процедуры | C20: =CEILING(F20*(1+G20*(E$3*E$4*E$5*E$9*E$13+E$12))*E$10, 0.1) -> 0.9 | F20: 0.5 | G20: 0.39
B21: Анализ ТЗ по результатам отборочной процедуры | C21: =CEILING(F21*(1+G21*(E$3*E$4*E$5*E$9*E$13+E$12))*E$10, 0.1) -> 0.9 | F21: 0.5 | G21: 0.39
B22: Подготовка АЗ для договора, согласование содержания договора | C22: =CEILING(F22*(1+G22*(E$3*E$4*E$5*E$9*E$13+E$12))*1, 0.1) -> 0.7 | F22: 0.5 | G22: 0.15
B23: Подготовка приложения к договору | C23: =CEILING(F23*(1+G23*(E$3*E$4*E$5*E$9*E$13+E$12))*1, 0.1) -> 0.7 | F23: 0.5 | G23: 0.15
B24: Доработка внутренней документации и инфрмационных ресурсов группы | C24: =CEILING(F24*(1+G24*(E$5*E$9+E7+E10))*E$3, 0.1) -> 0.8 | F24: 0.5 | G24: 0.2
B25: ИТОГО: | C25: =CEILING(SUM(C15:C24), 1) -> 8
C26: =C25*Параметры!$B$2 -> 243200
B28: Сопровождение юридического обеспечения нужно в СА?

Sheet OUT 2172030 ТР
B1: 260 Решение по обмену данными
B2: Параметр работ | C2: Значение параметра | E2: Влияние | F2: вар 1 | G2: вар 2 | H2: вар 3 | I2: вар 4 | J2: вар 5 | K2: вар 6 | L2: вар 7
B3: Инициировано предыдущим этапом (например, инициировано загрузкой, в которой уже прошла часть аналитики) | C3: Нет | E3: =IF(C3="Нет", G3, IF(C3="Да", H3, "")) -> 1 | G3: 1 | H3: 0.75
B4: Новое решение или доработка существующего | C4: Неизвестно | E4: =IF(C4="Неизвестно", F4, IF(C4="Доработка", G4, IF(C4="Новое", H4, ""))) -> 1 | F4: 1 | G4: 0.75 | H4: 1.1
B5: Сложность предметной области. Оценивается лидером команды/стрима исполнителя на основании опыта и профиля команды. | C5: Средняя | E5: =IF(C5="Неизвестно", F5, IF(C5="Низкая", G5, IF(C5="Средняя", H5, IF(C5="Высокая", I5, "")))) -> 1 | F5: 1.25 | G5: 0.75 | H5: 1 | I5: 1.5
B6: Объем запроса по сущностям. Ориентировочное соотвествие оценки к сущностям: Т: 1-4 М: 5-9 С: 9-15 К: 15-20 Б: 20-25 М: 25+. Соотвествие не точное и может отличаться. Оценивается лидером команды/стрима исполнителя на опыта работы с подобными сущностями и количества описывающих сущность атрибутов. | C6: Среднее | E6: =IF(C6="Неизвестно", F6, IF(C6="Точечное", G6, IF(C6="Малое", H6, IF(C6="Среднее", I6, IF(C6="Крупное", J6, IF(C6="Большое", K6, IF(C6="Масштабное", L6, ""))))))) -> 1 | F6: 1.25 | G6: 0.5 | H6: 0.75 | I6: 1 | J6: 1.25 | K6: 1.5 | L6: 1.75
B7: Детализация и ясность запроса в RDS или ином артефакте, предоставляемые заказчиком | C7: Неизвестно | E7: =IF(C7="Неизвестно", F7, IF(C7="Низкая", G7, IF(C7="Средняя", H7, IF(C7="Высокая", I7, "")))) -> 1 | F7: 1 | G7: 1.5 | H7: 1.25 | I7: 0.75
B8: Известны ли все стеикхолдеры (владелец сервиса, разработчик модели / витрин, РП и тд.) | C8: Неизвестно | E8: =IF(C8="Неизвестно", F8, IF(C8="Да", G8, IF(C8="Нет", H8, ""))) -> 1 | F8: 1 | G8: 0.9 | H8: 1.1
B9: Данные необходимы заказчику непосредственно или через витрины / модель | C9: Неизвестно | E9: =IF(C9="Неизвестно", F9, IF(C9="Непосредственно", G9, IF(C9="Опосредованно", H9, ""))) -> 1 | F9: 1 | G9: 0.8 | H9: 1.2
B10: Необходимо ли заключение NDA | C10: Неизвестно | E10: =IF(C10="Неизвестно", F10, IF(C10="Да", G10, IF(C10="Нет", H10, ""))) -> 1 | F10: 1 | G10: 1.25 | H10: 0
B11: Согласен ли Источник на стандартную форму NDA | C11: Неизвестно | E11: =IF(C11="Неизвестно", F11, IF(C11="Да", G11, IF(C11="Нет", H11, ""))) -> 1 | F11: 1 | G11: 0.75 | H11: 1.25
B12: Есть ли юридические основания для реализация решения по обмену данными | C12: Неизвестно | E12: =IF(C12="Неизвестно", F12, IF(C12="Да", G12, IF(C12="Нет", H12, ""))) -> 1 | F12: 1 | G12: 0 | H12: 1.25
B13: Сложность реализации. Определяется техническим лидом команды/стрима исполнителя. | C13: Средняя | E13: =IF(C13="Неизвестно", F13, IF(C13="Низкая", G13, IF(C13="Средняя", H13, IF(C13="Высокая", I13, "")))) -> 1 | F13: 1.25 | G13: 0.75 | H13: 1 | I13: 1.5
B14: Решение предусматривает обмен конфиденциальными данными | C14: Неизвестно | E14: =IF(C14="Неизвестно", F14, IF(C14="Да", G14, IF(C14="Нет", H14, ""))) -> 1 | F14: 1 | G14: 1.25 | H14: 0
B15: Решение предусматривает хэширование/шифрование | C15: Неизвестно | E15: =IF(C15="Неизвестно", F15, IF(C15="Да", G15, IF(C15="Нет", H15, ""))) -> 1 | F15: 1 | G15: 1.25 | H15: 0.75
B16: Решение предусматривает двусторонний обмен данными | C16: Неизвестно | E16: =IF(C16="Неизвестно", F16, IF(C16="Да", G16, IF(C16="Нет", H16, ""))) -> 1 | F16: 1 | G16: 1.25 | H16: 0.75
B17: ИТОГО по стриму "Источники данных": | C17: =CEILING(SUM(C30, C46, C52), 1) -> 34
C18: =C17*Параметры!$B$2 -> 1033600
B19: 217 Состав работ команды Внешние Данные | C19: Объём, чд | F19: база | G19: зависимость
B20: Интервьюирование заказчика, подтверждение финансирования и обработка RDS | C20: =CEILING(F20*(1+G20*(E$5*E$6*E$7*E$8*E$9*E$15*E$16+E$12+E$14))*(E$3*E$4), 0.1) -> 0.9 | F20: 0.5 | G20: 0.248
B21: Планирование и работа с бэклогом | C21: =CEILING(F21*(1+G21*(E$3*E$4*E$5*E$7*E$8*E$9*E$15*E$16+E$10*E$11+E$12+E$14))*E$6, 0.1) -> 1.1 | F21: 1 | G21: 0.01
B22: Сбор и анализ требований | C22: =CEILING(F22*(1+G22*(E$5*E$6*E$7*E$8*E$9*E$15*E$16+E$14))*(E$3*E$4), 0.1) -> 1.2 | F22: 1 | G22: 0.08
B23: Оперативное обеспечение юридического основания или инициация этапа | C23: =CEILING(F23*(1+G23*(E$3*E$5*E$6*E$8*E$9*E$15*E$16+E$14))*E$12, 0.1) -> 0.6 | F23: 0.5 | G23: 0.07
B24: Составление модели данных s2t | C24: =CEILING(F24*(1+G24*(E$3*E$5*E$16))*(E$6*E$4), 0.1) -> 1.2 | F24: 1 | G24: 0.15
B25: Составление ТР | C25: =CEILING(F25*(1+G25*(E$3*E$5*E$6*E$8*E$9*E$15*E$16+E$14))*E$4, 0.1) -> 1.5 | F25: 1 | G25: 0.25
B26: Подготовка АЗ для заключения NDA, согласование содержания NDA | C26: =CEILING(F26*(1+G26*(E$3*E$4*E$5*E$6*E$8*E$9*E$16+E$14))*(E$10*E$11), 0.1) -> 0.6 | F26: 0.5 | G26: 0.046
B27: Согласование интеграции с ИБ и ЮБ | C27: =CEILING(F27*(1+G27*(E$3*E$4*E$5*E$6*E$8*E$16))*E$14, 0.1) -> 0.6 | F27: 0.5 | G27: 0.151
B28: Согласование АР, участие в Тестировании и ПСИ | C28: =CEILING(F28*(1+G28*(E$3*E$5*E$6*E$15*E$16+E$14))*E$4, 0.1) -> 0.9 | F28: 0.5 | G28: 0.322
B29: Доработка внутренней документации и инфрмационных ресурсов группы | C29: =CEILING(F29*(1+G29*(E$3*E$6*E$9))*E$4, 0.1) -> 0.9 | F29: 0.5 | G29: 0.8
B30: ИТОГО: | C30: =CEILING(SUM(C20:C29), 1) -> 10
C31: =C30*Параметры!$B$2 -> 304000
B32: 220 Состав работ команды "Облако данных ETL" / "Облако данных" * (ИС 1505) * Оценка делится пополам и распределяется по обеим командам. Какая именно команда будет реализовывать решение определяется после проработки запроса командой Внешние данные | C32: Объём, чд | F32: база | G32: зависимость | H32: макс
B33: Планирование и работа с бэклогом | C33: =CEILING(F33*(1+G33*(E$5*E$6*E$9*E$15*E$16+E$12+E$14))*(E$3*E$4), 0.1) -> 0.7 | F33: 0.5 | G33: 0.11 | H33: 1
B34: Согласование и корректировка входящих требований | C34: =CEILING(F34*G34, 0.1) -> 0.8 | F34: =C25 -> 1.5 | G34: 0.5 | H34: 2
B35: Согласование и проверка модели данных s2t | C35: =CEILING(F35*G35, 0.1) -> 0.5 | F35: =C24 -> 1.2 | G35: 0.4 | H35: 1
B36: Работа над артефактом АР | C36: =CEILING(F36*(1+G36*(E$3*E$5*E$6*E$15*E$16+E$14))*E$4, 0.1) -> 2.3 | F36: 1 | G36: 0.65 | H36: 5
B37: Работа над артефактами ТПиС, ПМИ | C37: =CEILING(F37*(1+G37*(E$3*E$5*E$6*E$15*E$16+E$14))*E$4, 0.1) -> 1 | F37: 0.5 | G37: 0.49 | H37: 2
B38: Работы по разворачиванию и настройке новой инфраструктуры | C38: =CEILING(F38*(1+G38*(E$3*E$5*E$6*E$15*E$16+E$14))*E$4, 0.1) -> 1.7 | F38: 0.5 | G38: 1.14 | H38: 4
B39: Согласование артефактов и заведение заявок на доступы | C39: =CEILING(F39*(1+G39*(E$3*E$5*E$6*E$15*E$16+E$14))*E$4, 0.1) -> 1 | F39: 0.5 | G39: 0.46 | H39: 2
B40: Разработка Решения | C40: =CEILING(F40*(1+G40*(E$3*E$5*E$6*E$15*E$16+E$14))*E$4, 1) -> 6 | F40: 1 | G40: 2.175 | H40: 14
...

Sheet OUT 218 БТ внеш
B1: Разработка БТ для витрин на внешних данных
B2: Параметр работ | C2: Значение параметра | E2: Влияние | F2: вар 1 | G2: вар 2 | H2: вар 3 | I2: вар 4 | J2: вар 5 | K2: вар 6 | L2: вар 7
B3: Инициировано предыдущим этапом (например, инициировано загрузкой, в которой уже прошла часть аналитики) | C3: Нет | E3: =IF(C3="Нет", G3, IF(C3="Да", H3, "")) -> 1 | G3: 1 | H3: 0.75
B4: Новое решение или доработка существующего | C4: Неизвестно | E4: =IF(C4="Неизвестно", F4, IF(C4="Доработка", G4, IF(C4="Новое", H4, ""))) -> 1 | F4: 1 | G4: 0.75 | H4: 1.1
B5: Сложность логики формирования витрины и предметной области. Оценивается лидером команды/стрима исполнителя на основании опыта и профиля команды. | C5: Средняя | E5: =IF(C5="Неизвестно", F5, IF(C5="Низкая", G5, IF(C5="Средняя", H5, IF(C5="Высокая", I5, "")))) -> 1 | F5: 1.25 | G5: 0.75 | H5: 1 | I5: 1.5
B6: Объем запроса по сущностям. Ориентировочное соотвествие оценки к сущностям: Т: 1-4 М: 5-9 С: 9-15 К: 15-20 Б: 20-25 М: 25+. Соотвествие не точное и может отличаться. Оценивается лидером команды/стрима исполнителя на опыта работы с подобными сущностями и количества описывающих сущность атрибутов. | C6: Среднее | E6: =IF(C6="Неизвестно", F6, IF(C6="Точечное", G6, IF(C6="Малое", H6, IF(C6="Среднее", I6, IF(C6="Крупное", J6, IF(C6="Большое", K6, IF(C6="Масштабное", L6, ""))))))) -> 1 | F6: 1.25 | G6: 0.5 | H6: 0.75 | I6: 1 | J6: 1.25 | K6: 1.5 | L6: 1.75
B7: Детализация и ясность запроса в RDS или ином артефакте, предоставляемые заказчиком | C7: Неизвестно | E7: =IF(C7="Неизвестно", F7, IF(C7="Низкая", G7, IF(C7="Средняя", H7, IF(C7="Высокая", I7, "")))) -> 1 | F7: 1 | G7: 1.5 | H7: 1.25 | I7: 0.75
B8: Известны ли все стеикхолдеры (владелец сервиса, разработчик модели / витрин, РП и тд.) | C8: Неизвестно | E8: =IF(C8="Неизвестно", F8, IF(C8="Да", G8, IF(C8="Нет", H8, ""))) -> 1 | F8: 1 | G8: 0.9 | H8: 1.1
B9: Данные необходимы заказчику непосредственно или через вторичные витрины / модель | C9: Неизвестно | E9: =IF(C9="Неизвестно", F9, IF(C9="Непосредственно", G9, IF(C9="Опосредованно", H9, ""))) -> 1 | F9: 1 | G9: 0.8 | H9: 1.2
B10: 218 Состав работ команды "Внешние Данные" | C10: Объём, чд | F10: база | G10: зависимость
B11: Интервьюирование заказчика, подтверждение финансирования и обработка RDS | C11: =CEILING(F11*(1+G11*(E$5*E$6*E$7*E$8*E$9))*(E$3*E$4), 0.1) -> 0.7 | F11: 0.5 | G11: 0.248
B12: Планирование и работа с бэклогом | C12: =CEILING(F12*(1+G12*(E$3*E$4*E$5*E$7*E$8*E$9))*E$6, 0.1) -> 1.1 | F12: 1 | G12: 0.01
B13: Сбор и анализ требований | C13: =CEILING(F13*(1+G13*(E$6*E$7*E$8*E$9))*(E$3*E$4*E$5), 0.1) -> 1.1 | F13: 1 | G13: 0.08
B14: Составление модели данных s2t | C14: =CEILING(F14*(1+G14*E$3)*(E$6*E$4*E$5), 0.1) -> 1.2 | F14: 1 | G14: 0.15
B15: Составление БТ | C15: =CEILING(F15*(1+G15*(E$3*E$6*E$8*E$9))*(E$4*E$5), 0.1) -> 1.3 | F15: 1 | G15: 0.25
B16: Согласование артефактов Озера данных, участие в Тестировании и ПСИ | C16: =CEILING(F16*(1+G16*(E$3*E$6))*(E$4*E$5), 0.1) -> 0.7 | F16: 0.5 | G16: 0.322
B17: Доработка внутренней документации и инфрмационных ресурсов группы | C17: =CEILING(F17*(1+G17*(E$3*E$6*E$9))*E$4, 0.1) -> 0.9 | F17: 0.5 | G17: 0.8
B18: ИТОГО: | C18: =CEILING(SUM(C11:C17), 1) -> 7
C19: =C18*Параметры!$B$2 -> 212800
B20: Состав работ стрима "Витрины и сервисы озера данных" (ВиСОД) команды "Витрины внешних данных" | C20: Объём, чд
B21: Работы команды "Витрины внешних данных" обязательны для реализации витрин. Перечень и оценка работ осуществляется командой "Витрины внешних данных" по обращению (обычно это 60+ чд). Исключением является только случай создания витрин для построяения моделей командами ДАДМ. В таком случае не пишутся БТ, а дорабатывается или пишется ТР. Перечень работ осуществляется 217/220/230 этопами.
B22: Создание витрин | C22: ~ 50-100 чд
B23: ИТОГО: | C23: ?
C24: ?

Sheet OUT 219 ТИС
B1: Ведение артефактов ТИС
B2: Параметр работ | C2: Значение параметра | E2: Влияние | F2: вар 1 | G2: вар 2 | H2: вар 3 | I2: вар 4 | J2: вар 5 | K2: вар 6 | L2: вар 7
B3: Объем изменения, вносимого в ТИС | C3: Среднее | E3: =IF(C3="Неизвестно", F3, IF(C3="Точечное", G3, IF(C3="Малое", H3, IF(C3="Среднее", I3, IF(C3="Крупное", J3, IF(C3="Большое", K3, IF(C3="Масштабное", L3, ""))))))) -> 1 | F3: 1.25 | G3: 0.5 | H3: 0.75 | I3: 1 | J3: 1.25 | K3: 1.5 | L3: 1.75
B4: Необходимо ли изучение регламентов Банка по ведению радактируемого раздела | C4: Да | E4: =IF(C4="Неизвестно", F4, IF(C4="Да", G4, IF(C4="Нет", H4, ""))) -> 1 | F4: 1 | G4: 1 | H4: 0
B5: Необходимо ли пеерсогласование артефакта | C5: Да | E5: =IF(C5="Неизвестно", F5, IF(C5="Да", G5, IF(C5="Нет", H5, ""))) -> 1 | F5: 1 | G5: 1 | H5: 0
B6: 219 Состав работ команды Внешние Данные | C6: Объём, чд | F6: база | G6: зависимость
B7: Сбор и анализ требований по изменениям | C7: =CEILING(F7*(1+G7*(E$3+E$4+E$5))*E$3, 0.1) -> 2 | F7: 1 | G7: 0.31
B8: Системный анализ | C8: =CEILING(F8*(1+G8*(E$3+E$4+E$5))*E$3, 0.1) -> 3.8 | F8: 2 | G8: 0.3
B9: Изучение регламентов Банка по ведению редактируемого раздела/ов | C9: =CEILING(F9*(1+G9*(E$3+E$5))*(E$3*E$4), 0.1) -> 0.8 | F9: 0.5 | G9: 0.3
B10: Редактирование артефакта | C10: =CEILING(F10*(1+G10*(E$3+E$4+E$5))*E$3, 0.1) -> 4.4 | F10: 2 | G10: 0.4
B11: Согласование артефакта | C11: =CEILING(F11*(1+G11*(E$3+E$4))*(E$5*E$3), 0.1) -> 0.8 | F11: 0.5 | G11: 0.3
B12: ИТОГО: | C12: =ROUND(SUM(C7:C11), 0) -> 12
C13: =C12*Параметры!$B$2 -> 364800

Sheet INN 210 И. внут
B1: Исследование и описание внутренних источников, выгрузка тестовых данных, мониторинг изменений источников
B2: Параметр работ | C2: Значение параметра | E2: Влияние | F2: вар 1 | G2: вар 2 | H2: вар 3 | I2: вар 4 | J2: вар 5 | K2: вар 6 | L2: вар 7
B3: Инициировано предыдущим этапом (например, инициировано загрузкой, в которой уже прошла часть аналитики) | C3: Нет | E3: =IF(C3="Нет", G3, IF(C3="Да", H3, "")) -> 1 | G3: 1 | H3: 0.75
B4: Сложность предметной области. Оценивается лидером команды/стрима исполнителя на основании опыта и профиля команды. | C4: Высокая | E4: =IF(C4="Неизвестно", F4, IF(C4="Низкая", G4, IF(C4="Средняя", H4, IF(C4="Высокая", I4, "")))) -> 1.5 | F4: 1.25 | G4: 0.75 | H4: 1 | I4: 1.5
B5: Объем запроса по сущностям. Ориентировочное соответствие оценки к сущностям: Т: 1-4 М: 5-9 С: 9-15 К: 15-20 Б: 20-25 М: 25+. Соответствие не точное и может отличаться. Оценивается лидером команды/стрима исполнителя на опыте работы с подобными сущностями и количества описывающих сущность атрибутов. | C5: Масштабное | E5: =IF(C5="Неизвестно", F5, IF(C5="Точечное", G5, IF(C5="Малое", H5, IF(C5="Среднее", I5, IF(C5="Крупное", J5, IF(C5="Большое", K5, IF(C5="Масштабное", L5, ""))))))) -> 1.75 | F5: 1.25 | G5: 0.5 | H5: 0.75 | I5: 1 | J5: 1.25 | K5: 1.5 | L5: 1.75
B6: Детализация и ясность запроса в RDS или ином артефакте, предоставляемые заказчиком | C6: Средняя | E6: =IF(C6="Неизвестно", F6, IF(C6="Низкая", G6, IF(C6="Средняя", H6, IF(C6="Высокая", I6, "")))) -> 1.25 | F6: 1 | G6: 1.5 | H6: 1.25 | I6: 0.75
B7: Определены ли исследуемые источник(и) или исследование предполагает их поиск | C7: Да | E7: =IF(C7="Неизвестно", F7, IF(C7="Да", G7, IF(C7="Нет", H7, ""))) -> 0.75 | F7: 1 | G7: 0.75 | H7: 1.25
B8: Конкретизированы ли искомые данные или состав/объём данных понадобится в каждом источнике определять в согласовании с заказчиком | C8: Да | E8: =IF(C8="Неизвестно", F8, IF(C8="Да", G8, IF(C8="Нет", H8, ""))) -> 0.75 | F8: 1 | G8: 0.75 | H8: 1.25
B9: 210 Состав работ команды Внутренние Данные | C9: Объём, чд | F9: база | G9: зависимость
B10: Уточнение требований, сбор первичной информации | C10: =CEILING(F10*(1+G10*E4*E5*E6*E7*E8)*E3, 0.1) -> 0.8 | F10: 0.5 | G10: 0.31
B11: Планирование и работа с бэклогом | C11: =CEILING(F11*(1+G11*(E3*E4*E5*E6*E7*E8)), 0.1) -> 0.9 | F11: 0.5 | G11: 0.33
B12: Сбор и анализ требований | C12: =CEILING(F12*(1+G12*(E4*E5*E6*E7*E8))*E3, 0.1) -> 0.9 | F12: 0.5 | G12: 0.4
B13: Исследование Источника/Поиск Данных | C13: =CEILING(F13*(1+G13*(E3*E4*E6*E8))*(E5*E7), 0.1) -> 2.4 | F13: 1 | G13: 0.55
B14: Анализ Данных/Связок/Проверка качества | C14: =CEILING(F14*(1+G14*(E3*E4*E6*E8))*(E5*E7), 0.1) -> 2.4 | F14: 1 | G14: 0.55
B15: Проработка вопросов с контрагентами | C15: =CEILING(F15*(1+G15*(E3*E4*E6*E8))*(E5*E7), 0.1) -> 2.4 | F15: 1 | G15: 0.55
B16: Запрос выгрузок, контроль получения | C16: =CEILING(F16*(1+G16*(E3*E4*E6*E8))*(E5*E7), 0.1) -> 2.4 | F16: 1 | G16: 0.55
B17: Оформление Аналитической Записки | C17: =CEILING(F17*(1+G17*E3)*(E4*E5), 0.1) -> 1.7 | F17: 0.5 | G17: 0.22
B18: Доработка внутренней документации и информационных ресурсов группы | C18: =CEILING(F18*(1+G18*E5)*E3, 0.1) -> 0.9 | F18: 0.5 | G18: 0.45
B19: Расследование проблем с качеством/контроль устранения | C19: =CEILING(F19*(1+G19)*(E4*E5), 0.1) -> 6.5 | F19: 2 | G19: 0.22
B20: ИТОГО: | C20: =ROUND(SUM(C10:C19), 0) -> 21
C21: =C20*Параметры!$B$2 -> 638400

Sheet INN 211 БТ внут
B1: Разработка БТ (ТР) по реализации процесса загрузки данных и по витринам на внешних/внутренних данных
B2: Параметр работ | C2: Значение параметра | E2: Влияние | F2: вар 1 | G2: вар 2 | H2: вар 3 | I2: вар 4 | J2: вар 5 | K2: вар 6 | L2: вар 7
B3: Инициировано предыдущим этапом (например, инициировано загрузкой, в которой уже прошла часть аналитики) | C3: Да | E3: =IF(C3="Нет", G3, IF(C3="Да", H3, "")) -> 0.75 | G3: 1 | H3: 0.75
B4: Новое решение или доработка существующего | C4: Доработка | E4: =IF(C4="Неизвестно", F4, IF(C4="Доработка", G4, IF(C4="Новое", H4, ""))) -> 0.75 | F4: 1 | G4: 0.75 | H4: 1.1
B5: Сложность логики формирования витрины и предметной области. Оценивается лидером команды/стрима исполнителя на основании опыта и профиля команды. | C5: Средняя | E5: =IF(C5="Неизвестно", F5, IF(C5="Низкая", G5, IF(C5="Средняя", H5, IF(C5="Высокая", I5, "")))) -> 1 | F5: 1.25 | G5: 0.75 | H5: 1 | I5: 1.5
B6: Объем запроса по сущностям. Ориентировочное соотвествие оценки к сущностям: Т: 1-4 М: 5-9 С: 9-15 К: 15-20 Б: 20-25 М: 25+. Соотвествие не точное и может отличаться. Оценивается лидером команды/стрима исполнителя на опыта работы с подобными сущностями и количества описывающих сущность атрибутов. | C6: Точечное | E6: =IF(C6="Неизвестно", F6, IF(C6="Точечное", G6, IF(C6="Малое", H6, IF(C6="Среднее", I6, IF(C6="Крупное", J6, IF(C6="Большое", K6, IF(C6="Масштабное", L6, ""))))))) -> 0.5 | F6: 1.25 | G6: 0.5 | H6: 0.75 | I6: 1 | J6: 1.25 | K6: 1.5 | L6: 1.75
B7: Детализация и ясность запроса в RDS или ином артефакте, предоставляемые заказчиком | C7: Высокая | E7: =IF(C7="Неизвестно", F7, IF(C7="Низкая", G7, IF(C7="Средняя", H7, IF(C7="Высокая", I7, "")))) -> 0.75 | F7: 1 | G7: 1.5 | H7: 1.25 | I7: 0.75
B8: Известны ли все стеикхолдеры (владелец сервиса, разработчик модели / витрин, РП и тд.) | C8: Нет | E8: =IF(C8="Неизвестно", F8, IF(C8="Да", G8, IF(C8="Нет", H8, ""))) -> 1.1 | F8: 1 | G8: 0.9 | H8: 1.1
B9: Данные необходимы заказчику непосредственно или через вторичные витрины / модель | C9: Непосредственно | E9: =IF(C9="Неизвестно", F9, IF(C9="Непосредственно", G9, IF(C9="Опосредованно", H9, ""))) -> 0.8 | F9: 1 | G9: 0.8 | H9: 1.2
B10: 211 Состав работ команды "Внутренние Данные" | C10: Объём, чд | F10: база | G10: зависимость
B11: Интервьюирование заказчика, подтверждение финансирования и обработка RDS | C11: =CEILING(F11*(1+G11*(E$5*E$6*E$7*E$8*E$9))*(E$3*E$4), 0.1) -> 0.4 | F11: 0.5 | G11: 0.248
B12: Планирование и работа с бэклогом | C12: =CEILING(F12*(1+G12*(E$3*E$4*E$5*E$7*E$8*E$9))*E$6, 0.1) -> 0.6 | F12: 1 | G12: 0.01
B13: Сбор Требований | C13: =CEILING(F13*(1+G13*(E$6*E$7*E$8*E$9))*(E$3*E$4*E$5), 0.1) -> 1.8 | F13: 3 | G13: 0.08
B14: Анализ Источников | C14: =CEILING(F14*(1+G14*(E$6*E$7*E$8*E$9))*(E$3*E$4*E$5), 0.1) -> 2.4 | F14: 4 | G14: 0.08
B15: Постановка RDS/План/Сроки | C15: =CEILING(F15*(1+G15*(E$6*E$7*E$8*E$9))*(E$3*E$4*E$5), 0.1) -> 1.2 | F15: 2 | G15: 0.08
B16: Проработка связок | C16: =CEILING(F16*(1+G16*E$3)*(E$6*E$4*E$5), 0.1) -> 1.3 | F16: 3 | G16: 0.15
B17: Описание Бизнес Требования (Шаблон) | C17: =CEILING(F17*(1+G17*(E$3*E$6*E$8*E$9))*(E$4*E$5), 0.1) -> 0.9 | F17: 1 | G17: 0.25
B18: Формирование прототипа | C18: =CEILING(F18*(1+G18*(E$3*E$6*E$8*E$9))*(E$4*E$5), 0.1) -> 3.3 | F18: 4 | G18: 0.25
B19: Проработка проверок | C19: =CEILING(F19*(1+G19*(E$3*E$6*E$8*E$9))*(E$4*E$5), 0.1) -> 2.5 | F19: 3 | G19: 0.25
B20: Передача БТ в разработку | C20: =CEILING(F20*(1+G20*(E$6*E$7*E$8*E$9))*(E$3*E$4*E$5), 0.1) -> 0.6 | F20: 1 | G20: 0.08
B21: Согласование артефактов Озера данных, участие в Тестировании и ПСИ | C21: =CEILING(F21*(1+G21*(E$3*E$6))*(E$4*E$5), 0.1) -> 0.5 | F21: 0.5 | G21: 0.322
B22: Доработка внутренней документации и инфрмационных ресурсов группы | C22: =CEILING(F22*(1+G22*(E$3*E$6*E$9))*E$4, 0.1) -> 0.5 | F22: 0.5 | G22: 0.8
B23: ИТОГО: | C23: =CEILING(SUM(C11:C22), 1) -> 16
C24: =C23*Параметры!$B$2 -> 486400
B25: Состав работ стрима "Витрины и сервисы озера данных" (ВиСОД) команды "Витрины внутренних данных" | C25: Объём, чд
B26: Работы команды "Витрины внутренних данных" обязательны для реализации витрин для любых задач. Перечень и оценка работ осуществляется командой "Витрины внутренних данных" по обращению (обычно это 60+ чд). Исключением является только случай создания витрин для построяения моделей командами ДАДМ при условии использования в них и внешних данных. В таком случае не пишутся БТ, а дорабатывается или пишется ТР. Перечень работ осуществляется 217/220/230 этопами.
B27: Создание витрин | C27: ~ 50-100 чд
B28: ИТОГО: | C28: ?
C29: ?

Sheet INN 212 Загрузка
B1: Организация процесса загрузки внутренних данных в Платформу данных для целей моделирования
B2: Параметр работ | C2: Значение параметра | E2: Влияние | F2: вар 1 | G2: вар 2 | H2: вар 3 | I2: вар 4 | J2: вар 5 | K2: вар 6 | L2: вар 7
B3: Сложность | C3: L1 | E3: =IF(C3="L1", F3, IF(C3="L2", G3, IF(C3="L3", H3, ""))) -> 0.5 | F3: 0.5 | G3: 1 | H3: 1.5
B4: 212 Состав работ команды "Внутренние Данные" | C4: Объём, чд | F4: база | G4: зависимость
B5: Формирование плана интеграций/согласование сроков | C5: =CEILING(F5*E$3, 0.1) -> 1.5 | F5: 3
B6: Корректировка/Согласование документации (АИС/Протоколы/Ролевая Модель)) | C6: =CEILING(F6*E$3, 0.1) -> 2.5 | F6: 5
B7: Ведение активностей по интеграции (Лидирование/Сопровождение) | C7: =CEILING(F7*E$3, 0.1) -> 2.5 | F7: 5
B8: Тестирование (ПРЕДПСИ/ПСИ/Доработки после тестирования) | C8: =CEILING(F8*E$3, 0.1) -> 2.5 | F8: 5
B9: Проверка на ПРОМ Контуре | C9: =CEILING(F9*E$3, 0.1) -> 2 | F9: 4
B10: ИТОГО: | C10: =CEILING(SUM(C5:C9), 1) -> 11
C11: =C10*Параметры!$B$2 -> 334400
B12: А кто делает загрузку? ВиСОД | C12: Объём, чд
B13: ...
B14: ... | C14: ...
B15: ИТОГО: | C15: ?
C16: ?

Sheet Параметры
A1: Финансовые параметры
A2: Ставка за день | B2: =B3*8 -> 30400
A3: Ставка за час | B3: 3800
A4: Коэф.сложности INN
A5: L1 Например: Исследование интегрированного Источника/Ранее было похожее исследование + наличие активных контрагентов | B5: 0.5
A6: L2 Например: Значительное кол-во открытых вопросов/Ранее не исслед тематика, проблемы с качеством/Необходим поиск консультантов | B6: 1.5
A7: L3 Например: Исследование неинтегрированного источника,отсутсвие консультантов,необх получение выгрузкок (СЗ и т.д.) | B7: 2

Sheet СА Параметры
A1: Стрим | B1: Блок | C1: Раздел | D1: Тип | E1: Название оригинальное | F1: Название | G1: Контекст | H1: Результат выбора | I1: Вопросы | J1: Комментарий | K1: Справочник
A2: ИД. Внутренний | B2: Детальная Информация | C2: Арх.Компонент.Система источник | D2: Ручной | E2: Наличие реплики в DAPP (да/нет) | G2: Этап 210 | H2: 1. Берем чд из списка констант стандартных задач источников этапа 210 2а. Если да, выводится типовая работа с базовым чд 2б. Если нет, выводится типовая работа с базовым чд * на коэфициент 1.5
A3: ИД. Внутренний | B3: Детальная Информация | C3: Арх.Компонент.Система источник | D3: Ручной | E3: Требования по Источникам не понятны | G3: Этап 210 | H3: 1а. Если чекбокс не стоит, базовые чд источников из констант этапа 210 1б. Если стоит, умножаем базовые чд на 0.3, итоговую цифру добавляем к общим чд источника | I3: Что имеется в виду (количество потоков, количество атрибутов и т.п.)? | K3: Тип источника данных (внуренний/внешний)
A4: ИД. Внутренний | B4: Детальная Информация | C4: Арх.Компонент.Система источник | D4: Ручной | E4: Кол-во доп неопределенных на данный момент Источников/Тематик (риск привнесения новых требований) | G4: Этап 210 | H4: Берем чд из списка констант стандартных задач источников этапа 210 Если да, то базовые чд уножаем на х1.5 Остальные параметры не участвуют в рассчете | I4: Чем отличается от предыдущего пункта? Что понимается под неопределенным источником?
A5: ИД. Внутренний | B5: Детальная Информация | C5: Арх.Компонент.Объект данных | D5: Вычисляемый | E5: Кол-во источников в витрине | G5: Этап 211 | H5: Если кол-во источников в витрине больше 5, то добавляется коэффциент к Базовым чд вычисляемый по формуле - кол-во текущих источников в витрине / 5 и полученный коэффициент умножаем на кол-во чд из Базовых этапа 211 | J5: В явном виде параметр пользователем не заполняется.
A6: ИД. Внутренний | B6: Детальная Информация | C6: Арх.Компонент.Объект данных | D6: Ручной | E6: Неопределенный на данный момент Источников/Метрик с неопредел.логикой расчета (риск привнесения новых требований) | G6: Этап 211 | H6: Кол-во источников умножается на базовый коэф х10, этап 211 | I6: Чем отличается от строки 4? Корректно ли такое различие в коэффициентах? | J6: Неизвестно количество, логика метрик, в т.ч. источников для их расчета
A7: ИД. Внутренний | B7: Детальная Информация | C7: Арх.Компонент.Процесс обработки данных | D7: Ручной | E7: источников к интеграции в ПД(Высокая готовность (не требуются доработки)+простая архитектура) | G7: Этап 211 | H7: Если да, Берем итоговый чд из списка констант стандартных задач витрин, этапа 211 и умножаем на коэф 0.5 | I7: Уточнить состав задачи. Объединить 3 параметра в один - простая интеграция коэф 0.5, средняя коэф 0.8, сложная коэф 1.2
A8: ИД. Внутренний | B8: Детальная Информация | C8: Арх.Компонент.Процесс обработки данных | D8: Ручной | E8: источников к интеграции в ПД(Доработки ИС (ЛМД,и т.д)+простая архитектура) | G8: Этап 211 | H8: Если да, Берем итоговый чд из списка констант стандартных задач витрин, этапа 211 и умножаем на коэф 0.8
A9: ИД. Внутренний | B9: Детальная Информация | C9: Арх.Компонент.Процесс обработки данных | D9: Ручной | E9: источников сложная интеграция (проработка архитектуры,доработка источника) | G9: Этап 211 | H9: Если да, Берем итоговый чд из списка констант стандартных задач витрин, этапа 211 и умножаем на коэф 1.2
A10: ИД. Внутренний | B10: Детальная Информация | C10: Арх.Компонент.Объект данных | D10: Ручной | E10: Количество витрин к выводу в ПРОМ (общее) | G10: Этап 212 | H10: Если да, Берем итоговый чд из списка констант стандартных задач прома, этапа 212 (до 20 метрик по умолчанию) | I10: Реализуется через 2 параметра: Признак промышленной витрины Количество метрик | J10: Что понимается под витриной (источник или итоговый приемник)
A11: ИД. Внутренний | B11: Детальная Информация | C11: Арх.Компонент.Объект данных | D11: Ручной | E11: Кол-во витрин до 20 метрик | G11: Этап 212
A12: ИД. Внутренний | B12: Детальная Информация | C12: Арх.Компонент.Объект данных | D12: Ручной | E12: 20-50 метрик | G12: Этап 212 | H12: Если да, Берем итоговый чд из списка констант стандартных задач прома, этапа 212 + итоговый чд * 0.2
A13: ИД. Внутренний | B13: Детальная Информация | C13: Арх.Компонент.Объект данных | D13: Ручной | E13: >50 метрик | G13: Этап 212 | H13: Если да, Берем итоговый чд из списка констант стандартных задач прома, этапа 212 + итоговый чд * 0.4
A14: ИД. Внутренний | B14: Детальная Информация | C14: Арх.Компонент.Система источник | D14: Ручной | E14: Количество источников к выводу в ПРОМ (готовы к интеграции, доработки выполнены) | G14: Этап 212 | H14: Если да, Берем итоговый чд из списка констант стандартных задач прома, этапа 212 * 0.5 | I14: Уточнить смысл пункта Как вариант - параметр "Сложность интеграции" с 3-мя коэффициентами | J14: Что понимается под витриной (источник или итоговый приемник)
A15: ИД. Внутренний | B15: Детальная Информация | C15: Арх.Компонент.Система источник | D15: Ручной | E15: источников к выводу в ПРОМ (необходима доработка) | G15: Этап 212 | H15: Если да, Берем итоговый чд из списка констант стандартных задач прома, этапа 212 * 0.8 | I15: Уточнить смысл пункта Как вариант - параметр "Сложность интеграции" с 3-мя коэффициентами
A16: ИД. Внутренний | B16: Детальная Информация | C16: Арх.Компонент.Система источник | D16: Ручной | E16: интеграций с промежуточными системами (например СХК,СФП, и тд) | G16: Этап 212 | H16: Если да, Берем итоговый чд из списка констант стандартных задач прома, этапа 212 * 1.5 | I16: Уточнить смысл пункта Как вариант - параметр "Сложность интеграции" с 3-мя коэффициентами
A17: ИД. Внутренний | B17: Детальная Информация | C17: Арх.Компонент.Система источник | D17: Ручной | E17: Количество объектов для мониторинга (таблиц/ источника/Витрины) | G17: Этап 230 | H17: Этап 230. Если да, то мониторинг для 1 объекта (источника/витрины) +3чд | I17: Что понимается под мониторингом? Нужно ли дублировать параметр и в источники, и в витрины или это параметр Источников данных
A18: ИД. Внешний | B18: ? | C18: ? | D18: Ручной | E18: Инициировано предыдущим этапом (например, инициировано загрузкой, в которой уже прошла часть аналитики) | F18: ? | G18: Этап 214 | H18: Берется cостав работ команды Внешние Данные Этапа 214 из справочника (#7 справочник, константы брать при всех коэфициентах = 1), и если стоит да, этот базовый состав работ * 0.75, по умолчанию 1 | I18: Применения параметра в структуре СА СУМ воспринимается сложно. Кроме того, для этапа 214 нет предыдущего | K18: Тип системы-источника: 1) Внутренний, 2) Внешний
A19: ИД. Внешний | B19: ? | C19: ? | D19: Ручной | E19: Сложность предметной области. Оценивается лидером команды/стрима исполнителя на основании опыта и профиля команды. | F19: ? | G19: Этап 214 | H19: Берется cостав работ команды Внешние Данные Этапа 214 из справочника (#7 справочник, константы брать при всех коэфициентах = 1): по умолчанию средняя - коэф 1, неизвестно - коэф 1.25, высокая - коэф 1.5, низкая - коэф 0.75 | I19: Дублируется на всех этапах. Выглядит как дубль параметры "Общая неопределенность"?
A20: ИД. Внешний | B20: ? | C20: ? | D20: Ручной | E20: Объем запроса по сущностям. Ориентировочное соответствие оценки к сущностям: Т: 1-4 М: 5-9 С: 9-15 К: 15-20 Б: 20-25 М: 25+. Соответствие не точное и может отличаться. Оценивается лидером команды/стрима исполнителя на опыте работы с подобными сущностями и количества описывающих сущность атрибутов. | F20: ? | G20: Этап 214 | H20: Берется cостав работ команды Внешние Данные Этапа 214 из справочника (#7 справочник, константы брать при всех коэфициентах = 1):, по умолчанию среднее - коэф 1, неизвестное и крупное - 1.25, большое - 1.5, масштабное - 1.75, точечное - 0.5, малое - 0.75 | I20: Дублируется на всех этапах. Выглядит как дубль параметры "Общая неопределенность"?
A21: ИД. Внешний | B21: ? | C21: ? | D21: Ручной | E21: Детализация и ясность запроса в RDS или ином артефакте, предоставляемые заказчиком | F21: ? | G21: Этап 214 | H21: Берется cостав работ команды Внешние Данные Этапа 214 из справочника (#7 справочник, константы брать при всех коэфициентах = 1):, по умолчанию неизвестное - коэф 1, низкая - 1.5, средняя - 1.25, высокая - 0.75 | I21: Дублируется на всех этапах. Выглядит как дубль параметры "Общая неопределенность"? Аналог параметры "Требования по источниками не понятны" ИД. Внутренний?
A22: ИД. Внешний | B22: Детальная Информация | C22: Арх.Компонент.Система источник? | D22: Ручной | E22: Определены ли исследуемые источник(и) или исследование предполагает их поиск | F22: ? | G22: Этап 214 | H22: Берется cостав работ команды Внешние Данные Этапа 214 из справочника (#7 справочник, константы брать при всех коэфициентах = 1):, по умолчанию неизвестное - коэф 1, да - 0.75, нет - 1.25 | I22: Это аналог поля с СА источников данных внутренних - Кол-во доп неопределенных на данный момент Источников/Тематик (риск привнесения новых требований) ?
A23: ИД. Внешний | B23: Детальная Информация | C23: Арх.Компонент.Система источник? | D23: Ручной | E23: Конкретизированы ли искомые данные или состав/объём данных понадобится в каждом источнике определять в согласовании с заказчиком | F23: ? | G23: Этап 214 | H23: Берется cостав работ команды Внешние Данные Этапа 214 из справочника (#7 справочник, константы брать при всех коэфициентах = 1):, по умолчанию неизвестное - коэф 1, да - 0.75, нет - 1.25 | I23: Это аналог поля с СА источников данных внутренних - Кол-во доп неопределенных на данный момент Источников/Тематик (риск привнесения новых требований) ?
A24: ИД. Внешний | B24: Детальная Информация | C24: Арх.Компонент.Система-источник | D24: Ручной | E24: Необходимо ли заключение NDA | F24: NDA: 1) Нет, 2) Стандартное, 3) Нестандартное | G24: Этап 214 | H24: Берется cостав работ команды Внешние Данные Этапа 214 из справочника (#7 справочник, константы брать при всех коэфициентах = 1):, по умолчанию неизвестное - коэф 1, да - 1.25, нет - 0 | I24: Объединить параметры NDA
A25: ИД. Внешний | B25: Детальная Информация | C25: Арх.Компонент.Система-источник | D25: Ручной | E25: Согласен ли Источник на стандартную форму NDA | F25: NDA: 1) Нет, 2) Стандартное, 3) Нестандартное | G25: Этап 214 | H25: Берется cостав работ команды Внешние Данные Этапа 214 из справочника (#7 справочник, константы брать при всех коэфициентах = 1):, по умолчанию неизвестное - коэф 1, да - 0.75, нет - 1.25 | I25: Объединить параметры NDA
A26: ИД. Внешний | B26: Детальная Информация | C26: Арх.Компонент.Система-источник | D26: Ручной | E26: Предмет исследования включает в себя конфиденциальные данные | F26: Наличие конфиденциальных данных | G26: Этап 214 | H26: Берется cостав работ команды Внешние Данные Этапа 214 из справочника (#7 справочник, константы брать при всех коэфициентах = 1):, по умолчанию неизвестное - коэф 1, да - 1.25, нет - 0
A27: ИД. Внешний | B27: ? | C27: Арх.Компонент.Система-источник | D27: Ручной | E27: Инициировано предыдущим этапом (например, инициировано загрузкой, в которой уже прошла часть аналитики) | F27: Отсутствует | G27: Этап 215, 220 | H27: Берется cостав работ команды Внешние Данные Этапа 214 из справочника (#7 справочник, константы брать при всех коэфициентах = 1), и если стоит да, этот базовый состав работ * 0.75, по умолчанию 1 | I27: Применения параметра в структуре СА СУМ воспринимается сложно. Кроме того, для этапа 214 нет предыдущего
A28: ИД. Внешний | B28: ? | C28: Арх.Компонент.Система-источник | D28: Ручной | E28: Сложность предметной области. Оценивается лидером команды/стрима исполнителя на основании опыта и профиля команды. | F28: Отсутствует | G28: Этап 215, 220 | H28: Берется cостав работ команды Внешние Данные Этапа 214 из справочника (#7 справочник, константы брать при всех коэфициентах = 1): по умолчанию средняя - коэф 1, неизвестно - коэф 1.25, высокая - коэф 1.5, низкая - коэф 0.75 | I28: Дублируется на всех этапах. Выглядит как дубль параметры "Общая неопределенность"?
A29: ИД. Внешний | B29: ? | C29: Арх.Компонент.Система-источник | D29: Ручной | E29: Объем запроса по сущностям. Ориентировочное соответствие оценки к сущностям: Т: 1-4 М: 5-9 С: 9-15 К: 15-20 Б: 20-25 М: 25+. Соответствие не точное и может отличаться. Оценивается лидером команды/стрима исполнителя на опыте работы с подобными сущностями и количества описывающих сущность атрибутов. | F29: Отсутствует | G29: Этап 215, 220 | H29: Берется cостав работ команды Внешние Данные Этапа 214 из справочника (#7 справочник, константы брать при всех коэфициентах = 1):, по умолчанию среднее - коэф 1, неизвестное и крупное - 1.25, большое - 1.5, масштабное - 1.75, точечное - 0.5, малое - 0.75 | I29: Дублируется на всех этапах. Выглядит как дубль параметры "Общая неопределенность"?
A30: ИД. Внешний | B30: ? | C30: Арх.Компонент.Система-источник | D30: Ручной | E30: Детализация и ясность запроса в RDS или ином артефакте, предоставляемые заказчиком | F30: Отсутствует | G30: Этап 215, 220 | H30: Берется cостав работ команды Внешние Данные Этапа 214 из справочника (#7 справочник, константы брать при всех коэфициентах = 1):, по умолчанию неизвестное - коэф 1, низкая - 1.5, средняя - 1.25, высокая - 0.75 | I30: Дублируется на всех этапах. Выглядит как дубль параметры "Общая неопределенность"? Аналог параметры "Требования по источниками не понятны" ИД. Внутренний?
A31: ИД. Внешний | B31: Детальная Информация | C31: Арх.Компонент.Система-источник | D31: Ручной | E31: Новый пилот или повторный | F31: Пилот: 1) Нет, 2) Первичный, 3) Повторный | G31: Этап 215, 220 | H31: Берется cостав работ команды Внешние Данные Этапов 215 и 220 из справочников (#8 и #9 справочники, константы брать при всех коэфициентах = 1):, по умолчанию неизвестное - коэф 1, новый - 1.1, повторный - 0.75 | I31: Аналог параметра "Требуется пилот" в Основной информации? Может либыть пилот только по данным, но не по модели?
A32: ИД. Внешний | B32: Детальная Информация | C32: Арх.Компонент.Система-источник | D32: Ручной | E32: Необходимо ли заключение NDA | F32: Отсутствует | G32: Этап 214 | H32: Берется cостав работ команды Внешние Данные Этапа 214 из справочника (#7 справочник, константы брать при всех коэфициентах = 1):, по умолчанию неизвестное - коэф 1, да - 1.25, нет - 0 | I32: Объединить параметры NDA
A33: ИД. Внешний | B33: Детальная Информация | C33: Арх.Компонент.Система-источник | D33: Ручной | E33: Согласен ли Источник на стандартную форму NDA | F33: Отсутствует | G33: Этап 214 | H33: Берется cостав работ команды Внешние Данные Этапа 214 из справочника (#7 справочник, константы брать при всех коэфициентах = 1):, по умолчанию неизвестное - коэф 1, да - 0.75, нет - 1.25 | I33: Объединить параметры NDA
A34: ИД. Внешний | B34: Детальная Информация | C34: Арх.Компонент.Система-источник | D34: Ручной | E34: Есть ли юридические основания для проведения пилота / разовой загрузки | F34: Юридическое основание для пилота: 1) Есть, 2) Нет | G34: Этап 215, 220 | H34: Берется cостав работ команды Внешние Данные Этапов 215 и 220 из справочников (#8 и #9 справочники, константы брать при всех коэфициентах = 1):, по умолчанию неизвестное - коэф 1, да - 1.25, нет - 0 | I34: Из 16 базовых работ этапов 215 и 220, коэффициент учитывается только в 3. Какие Можно ли этот пункт вынести в чекбокс и константы 2/3/4чд?
A35: ИД. Внешний | B35: Детальная Информация | C35: Арх.Компонент.Система-источник | D35: Ручной | E35: Пилот / разовая загрузка предусматривает обмен конфиденциальными данными | F35: Наличие конфиденциальных данных | G35: Этап 215, 220 | H35: Берется cостав работ команды Внешние Данные Этапов 215 и 220 из справочников (#8 и #9 справочники, константы брать при всех коэфициентах = 1):, по умолчанию неизвестное - коэф 1, да - 1.25, нет - 0
A36: ИД. Внешний | B36: Детальная Информация | C36: Арх.Компонент.Система-источник | D36: Ручной | E36: Пилот / разовая загрузка предусматривает хэширование/шифрование | F36: Требуется хэширование/ шифрование | G36: Этап 215, 220 | H36: Берется cостав работ команды Внешние Данные Этапов 215 и 220 из справочников (#8 и #9 справочники, константы брать при всех коэфициентах = 1):, по умолчанию неизвестное - коэф 1, да - 1.25, нет - 0.9
A37: ИД. Внешний | B37: Детальная Информация | C37: Арх.Компонент.Система-источник | D37: Ручной | E37: Пилот / разовая загрузка предусматривает двусторонний обмен данными | F37: Двусторонний обмен данными | G37: Этап 215, 220 | H37: Берется cостав работ команды Внешние Данные Этапов 215 и 220 из справочников (#8 и #9 справочники, константы брать при всех коэфициентах = 1):, по умолчанию неизвестное - коэф 1, да - 1.25, нет - 0.9
A38: ИД. Внешний | B38: Источники данных? | C38: Арх.Компонент.Система-источник | E38: Предусматривает ли пилот разовую загрузку командой Облако в ИС харнения Банка? | G38: Этап 215, 220 | I38: Это работы внешнего стрима?
A39: ИД. Внешний | B39: ? | C39: Арх.Компонент.Система-источник | D39: Ручной | E39: Инициировано предыдущим этапом (например, инициировано загрузкой, в которой уже прошла часть аналитики) | F39: Отсутствует | G39: 216 | H39: Берется cостав работ команды Внешние Данные Этапа 214 из справочника (#7 справочник, константы брать при всех коэфициентах = 1), и если стоит да, этот базовый состав работ * 0.75, по умолчанию 1 | I39: Применения параметра в структуре СА СУМ воспринимается сложно. Кроме того, для этапа 214 нет предыдущего
A40: ИД. Внешний | B40: ? | C40: Арх.Компонент.Система-источник | D40: Ручной | E40: Сложность предметной области. Оценивается лидером команды/стрима исполнителя на основании опыта и профиля команды. | F40: Отсутствует | G40: 216 | H40: Берется cостав работ команды Внешние Данные Этапа 214 из справочника (#7 справочник, константы брать при всех коэфициентах = 1): по умолчанию средняя - коэф 1, неизвестно - коэф 1.25, высокая - коэф 1.5, низкая - коэф 0.75 | I40: Дублируется на всех этапах. Выглядит как дубль параметры "Общая неопределенность"?
...

Sheet СА Работы
A1: Стрим | B1: Арх. Компонент | C1: Название оригинальное | D1: Название | E1: Контекст | F1: Тип работы | G1: Наличие норматива | H1: Параметр-триггер | I1: Параметры трудоемкости | J1: Кто может заполнить | K1: Вопросы | L1: Справочник
A2: ИД. Внутренний | B2: Арх.Компонент.Система источник | C2: Уточнение требований, сбор первичной информации | E2: Этап 210 | F2: Опциональная | G2: 1 | H2: Тип источника (внутренний) | I2: Наличие реплики в DAPP (количества да/нет), Требования по Источникам не понятны, Кол-во доп неопределенных на данный момент Источников/Тематик (риск привнесения новых требований) | K2: Дублируют ли параметры общую неопределенность? | L2: Тип системы-источника: 1) Внутренний, 2) Внешний
A3: ИД. Внутренний | B3: Арх.Компонент.Система источник | C3: Исследование Источника/Поиск Данных | E3: Этап 210 | F3: Опциональная | G3: 2 | H3: Тип источника (внутренний) | I3: Наличие реплики в DAPP (количества да/нет), Требования по Источникам не понятны, Кол-во доп неопределенных на данный момент Источников/Тематик (риск привнесения новых требований) | K3: Какие виды работ возможны (разработка с нуля, доработка, и так далее)? Будет ли различатся трудоемкость для разных видов работ?
A4: ИД. Внутренний | B4: Арх.Компонент.Система источник | C4: Анализ Данных, Связок, Проверка качества | E4: Этап 210 | F4: Опциональная | G4: 3 | H4: Тип источника (внутренний) | I4: Наличие реплики в DAPP (количества да/нет), Требования по Источникам не понятны, Кол-во доп неопределенных на данный момент Источников/Тематик (риск привнесения новых требований)
A5: ИД. Внутренний | B5: Арх.Компонент.Система источник | C5: Проработка вопросов с контрагентами | E5: Этап 210 | F5: Опциональная | G5: 3 | H5: Тип источника (внутренний) | I5: Наличие реплики в DAPP (количества да/нет), Требования по Источникам не понятны, Кол-во доп неопределенных на данный момент Источников/Тематик (риск привнесения новых требований)
